test
channel arkbFg-HLAZlYjJi, account +380 68 612 76 31.session
Traceback (most recent call last):
  File "C:\Users\пользователь\Desktop\Бот коменнст\comments\main.py", line 243, in join_channel
    res = await client(ImportChatInviteRequest(hash=link))
          ^^^^^^^^^^^^^^^^^^^^^^^^^^^^^^^^^^^^^^^^^^^^^^^^
  File "C:\Users\пользователь\AppData\Roaming\Python\Python311\site-packages\telethon\client\users.py", line 30, in __call__
    return await self._call(self._sender, request, ordered=ordered)
           ^^^^^^^^^^^^^^^^^^^^^^^^^^^^^^^^^^^^^^^^^^^^^^^^^^^^^^^^
  File "C:\Users\пользователь\AppData\Roaming\Python\Python311\site-packages\telethon\client\users.py", line 84, in _call
    result = await future
             ^^^^^^^^^^^^
telethon.errors.rpcerrorlist.UserAlreadyParticipantError: The authenticated user is already a participant of the chat (caused by ImportChatInviteRequest)

channel arkbFg-HLAZlYjJi, account main.session
Traceback (most recent call last):
  File "C:\Users\пользователь\Desktop\Бот коменнст\comments\main.py", line 243, in join_channel
    res = await client(ImportChatInviteRequest(hash=link))
          ^^^^^^^^^^^^^^^^^^^^^^^^^^^^^^^^^^^^^^^^^^^^^^^^
  File "C:\Users\пользователь\AppData\Roaming\Python\Python311\site-packages\telethon\client\users.py", line 30, in __call__
    return await self._call(self._sender, request, ordered=ordered)
           ^^^^^^^^^^^^^^^^^^^^^^^^^^^^^^^^^^^^^^^^^^^^^^^^^^^^^^^^
  File "C:\Users\пользователь\AppData\Roaming\Python\Python311\site-packages\telethon\client\users.py", line 84, in _call
    result = await future
             ^^^^^^^^^^^^
telethon.errors.rpcerrorlist.UserAlreadyParticipantError: The authenticated user is already a participant of the chat (caused by ImportChatInviteRequest)

channel IwWCKB8933RkMTMy, account main.session
Traceback (most recent call last):
  File "C:\Users\пользователь\Desktop\Бот коменнст\comments\main.py", line 243, in join_channel
    res = await client(ImportChatInviteRequest(hash=link))
          ^^^^^^^^^^^^^^^^^^^^^^^^^^^^^^^^^^^^^^^^^^^^^^^^
  File "C:\Users\пользователь\AppData\Roaming\Python\Python311\site-packages\telethon\client\users.py", line 30, in __call__
    return await self._call(self._sender, request, ordered=ordered)
           ^^^^^^^^^^^^^^^^^^^^^^^^^^^^^^^^^^^^^^^^^^^^^^^^^^^^^^^^
  File "C:\Users\пользователь\AppData\Roaming\Python\Python311\site-packages\telethon\client\users.py", line 84, in _call
    result = await future
             ^^^^^^^^^^^^
telethon.errors.rpcerrorlist.UserAlreadyParticipantError: The authenticated user is already a participant of the chat (caused by ImportChatInviteRequest)

channel IwWCKB8933RkMTMy, account +380 68 612 76 31.session
Traceback (most recent call last):
  File "C:\Users\пользователь\Desktop\Бот коменнст\comments\main.py", line 243, in join_channel
    res = await client(ImportChatInviteRequest(hash=link))
          ^^^^^^^^^^^^^^^^^^^^^^^^^^^^^^^^^^^^^^^^^^^^^^^^
  File "C:\Users\пользователь\AppData\Roaming\Python\Python311\site-packages\telethon\client\users.py", line 30, in __call__
    return await self._call(self._sender, request, ordered=ordered)
           ^^^^^^^^^^^^^^^^^^^^^^^^^^^^^^^^^^^^^^^^^^^^^^^^^^^^^^^^
  File "C:\Users\пользователь\AppData\Roaming\Python\Python311\site-packages\telethon\client\users.py", line 84, in _call
    result = await future
             ^^^^^^^^^^^^
telethon.errors.rpcerrorlist.UserAlreadyParticipantError: The authenticated user is already a participant of the chat (caused by ImportChatInviteRequest)

channel arkbFg-HLAZlYjJi, account +380 68 612 76 31.session
Traceback (most recent call last):
  File "C:\Users\пользователь\Desktop\Бот коменнст\comments\main.py", line 243, in join_channel
    res = await client(ImportChatInviteRequest(hash=link))
          ^^^^^^^^^^^^^^^^^^^^^^^^^^^^^^^^^^^^^^^^^^^^^^^^
  File "C:\Users\пользователь\AppData\Roaming\Python\Python311\site-packages\telethon\client\users.py", line 30, in __call__
    return await self._call(self._sender, request, ordered=ordered)
           ^^^^^^^^^^^^^^^^^^^^^^^^^^^^^^^^^^^^^^^^^^^^^^^^^^^^^^^^
  File "C:\Users\пользователь\AppData\Roaming\Python\Python311\site-packages\telethon\client\users.py", line 84, in _call
    result = await future
             ^^^^^^^^^^^^
telethon.errors.rpcerrorlist.UserAlreadyParticipantError: The authenticated user is already a participant of the chat (caused by ImportChatInviteRequest)

channel https://t.me/joinchat/9SBFfSlkXZ44NTli, account main.session
Traceback (most recent call last):
  File "C:\Users\пользователь\Desktop\Бот коменнст\comments\main.py", line 279, in join_channel
    res = await client(JoinChannelRequest(await client.get_input_entity(link)))
                                          ^^^^^^^^^^^^^^^^^^^^^^^^^^^^^^^^^^^
  File "C:\Users\пользователь\AppData\Roaming\Python\Python311\site-packages\telethon\client\users.py", line 437, in get_input_entity
    await self._get_entity_from_string(peer))
    ^^^^^^^^^^^^^^^^^^^^^^^^^^^^^^^^^^^^^^^^
  File "C:\Users\пользователь\AppData\Roaming\Python\Python311\site-packages\telethon\client\users.py", line 574, in _get_entity_from_string
    raise ValueError(
ValueError: Cannot find any entity corresponding to "https://t.me/joinchat/9SBFfSlkXZ44NTli"

channel https://t.me/joinchat/VMLlgiAXZ8Q2ZTJi, account main.session
Traceback (most recent call last):
  File "C:\Users\пользователь\Desktop\Бот коменнст\comments\main.py", line 279, in join_channel
    res = await client(JoinChannelRequest(await client.get_input_entity(link)))
                                          ^^^^^^^^^^^^^^^^^^^^^^^^^^^^^^^^^^^
  File "C:\Users\пользователь\AppData\Roaming\Python\Python311\site-packages\telethon\client\users.py", line 437, in get_input_entity
    await self._get_entity_from_string(peer))
    ^^^^^^^^^^^^^^^^^^^^^^^^^^^^^^^^^^^^^^^^
  File "C:\Users\пользователь\AppData\Roaming\Python\Python311\site-packages\telethon\client\users.py", line 574, in _get_entity_from_string
    raise ValueError(
ValueError: Cannot find any entity corresponding to "https://t.me/joinchat/VMLlgiAXZ8Q2ZTJi"

channel https://t.me/horevica, account main.session
Traceback (most recent call last):
  File "C:\Users\пользователь\Desktop\Бот коменнст\comments\main.py", line 279, in join_channel
    res = await client(JoinChannelRequest(await client.get_input_entity(link)))
          ^^^^^^^^^^^^^^^^^^^^^^^^^^^^^^^^^^^^^^^^^^^^^^^^^^^^^^^^^^^^^^^^^^^^^
  File "C:\Users\пользователь\AppData\Roaming\Python\Python311\site-packages\telethon\client\users.py", line 30, in __call__
    return await self._call(self._sender, request, ordered=ordered)
           ^^^^^^^^^^^^^^^^^^^^^^^^^^^^^^^^^^^^^^^^^^^^^^^^^^^^^^^^
  File "C:\Users\пользователь\AppData\Roaming\Python\Python311\site-packages\telethon\client\users.py", line 84, in _call
    result = await future
             ^^^^^^^^^^^^
telethon.errors.rpcerrorlist.FloodWaitError: A wait of 112 seconds is required (caused by JoinChannelRequest)

channel https://t.me/gistapapapa, account main.session
Traceback (most recent call last):
  File "C:\Users\пользователь\Desktop\Бот коменнст\comments\main.py", line 279, in join_channel
    res = await client(JoinChannelRequest(await client.get_input_entity(link)))
          ^^^^^^^^^^^^^^^^^^^^^^^^^^^^^^^^^^^^^^^^^^^^^^^^^^^^^^^^^^^^^^^^^^^^^
  File "C:\Users\пользователь\AppData\Roaming\Python\Python311\site-packages\telethon\client\users.py", line 30, in __call__
    return await self._call(self._sender, request, ordered=ordered)
           ^^^^^^^^^^^^^^^^^^^^^^^^^^^^^^^^^^^^^^^^^^^^^^^^^^^^^^^^
  File "C:\Users\пользователь\AppData\Roaming\Python\Python311\site-packages\telethon\client\users.py", line 52, in _call
    raise errors.FloodWaitError(request=r, capture=diff)
telethon.errors.rpcerrorlist.FloodWaitError: A wait of 110 seconds is required (caused by JoinChannelRequest)

channel https://t.me/ukropernews, account main.session
Traceback (most recent call last):
  File "C:\Users\пользователь\Desktop\Бот коменнст\comments\main.py", line 279, in join_channel
    res = await client(JoinChannelRequest(await client.get_input_entity(link)))
          ^^^^^^^^^^^^^^^^^^^^^^^^^^^^^^^^^^^^^^^^^^^^^^^^^^^^^^^^^^^^^^^^^^^^^
  File "C:\Users\пользователь\AppData\Roaming\Python\Python311\site-packages\telethon\client\users.py", line 30, in __call__
    return await self._call(self._sender, request, ordered=ordered)
           ^^^^^^^^^^^^^^^^^^^^^^^^^^^^^^^^^^^^^^^^^^^^^^^^^^^^^^^^
  File "C:\Users\пользователь\AppData\Roaming\Python\Python311\site-packages\telethon\client\users.py", line 52, in _call
    raise errors.FloodWaitError(request=r, capture=diff)
telethon.errors.rpcerrorlist.FloodWaitError: A wait of 107 seconds is required (caused by JoinChannelRequest)

channel https://t.me/ukr_sof, account main.session
Traceback (most recent call last):
  File "C:\Users\пользователь\Desktop\Бот коменнст\comments\main.py", line 279, in join_channel
    res = await client(JoinChannelRequest(await client.get_input_entity(link)))
          ^^^^^^^^^^^^^^^^^^^^^^^^^^^^^^^^^^^^^^^^^^^^^^^^^^^^^^^^^^^^^^^^^^^^^
  File "C:\Users\пользователь\AppData\Roaming\Python\Python311\site-packages\telethon\client\users.py", line 30, in __call__
    return await self._call(self._sender, request, ordered=ordered)
           ^^^^^^^^^^^^^^^^^^^^^^^^^^^^^^^^^^^^^^^^^^^^^^^^^^^^^^^^
  File "C:\Users\пользователь\AppData\Roaming\Python\Python311\site-packages\telethon\client\users.py", line 52, in _call
    raise errors.FloodWaitError(request=r, capture=diff)
telethon.errors.rpcerrorlist.FloodWaitError: A wait of 105 seconds is required (caused by JoinChannelRequest)

channel https://t.me/ButusovPlus, account main.session
Traceback (most recent call last):
  File "C:\Users\пользователь\Desktop\Бот коменнст\comments\main.py", line 279, in join_channel
    res = await client(JoinChannelRequest(await client.get_input_entity(link)))
          ^^^^^^^^^^^^^^^^^^^^^^^^^^^^^^^^^^^^^^^^^^^^^^^^^^^^^^^^^^^^^^^^^^^^^
  File "C:\Users\пользователь\AppData\Roaming\Python\Python311\site-packages\telethon\client\users.py", line 30, in __call__
    return await self._call(self._sender, request, ordered=ordered)
           ^^^^^^^^^^^^^^^^^^^^^^^^^^^^^^^^^^^^^^^^^^^^^^^^^^^^^^^^
  File "C:\Users\пользователь\AppData\Roaming\Python\Python311\site-packages\telethon\client\users.py", line 52, in _call
    raise errors.FloodWaitError(request=r, capture=diff)
telethon.errors.rpcerrorlist.FloodWaitError: A wait of 103 seconds is required (caused by JoinChannelRequest)

channel https://t.me/bro_revisor, account main.session
Traceback (most recent call last):
  File "C:\Users\пользователь\Desktop\Бот коменнст\comments\main.py", line 279, in join_channel
    res = await client(JoinChannelRequest(await client.get_input_entity(link)))
          ^^^^^^^^^^^^^^^^^^^^^^^^^^^^^^^^^^^^^^^^^^^^^^^^^^^^^^^^^^^^^^^^^^^^^
  File "C:\Users\пользователь\AppData\Roaming\Python\Python311\site-packages\telethon\client\users.py", line 30, in __call__
    return await self._call(self._sender, request, ordered=ordered)
           ^^^^^^^^^^^^^^^^^^^^^^^^^^^^^^^^^^^^^^^^^^^^^^^^^^^^^^^^
  File "C:\Users\пользователь\AppData\Roaming\Python\Python311\site-packages\telethon\client\users.py", line 52, in _call
    raise errors.FloodWaitError(request=r, capture=diff)
telethon.errors.rpcerrorlist.FloodWaitError: A wait of 101 seconds is required (caused by JoinChannelRequest)

channel https://t.me/zahidwtf_official, account main.session
Traceback (most recent call last):
  File "C:\Users\пользователь\Desktop\Бот коменнст\comments\main.py", line 279, in join_channel
    res = await client(JoinChannelRequest(await client.get_input_entity(link)))
          ^^^^^^^^^^^^^^^^^^^^^^^^^^^^^^^^^^^^^^^^^^^^^^^^^^^^^^^^^^^^^^^^^^^^^
  File "C:\Users\пользователь\AppData\Roaming\Python\Python311\site-packages\telethon\client\users.py", line 30, in __call__
    return await self._call(self._sender, request, ordered=ordered)
           ^^^^^^^^^^^^^^^^^^^^^^^^^^^^^^^^^^^^^^^^^^^^^^^^^^^^^^^^
  File "C:\Users\пользователь\AppData\Roaming\Python\Python311\site-packages\telethon\client\users.py", line 52, in _call
    raise errors.FloodWaitError(request=r, capture=diff)
telethon.errors.rpcerrorlist.FloodWaitError: A wait of 99 seconds is required (caused by JoinChannelRequest)

channel https://t.me/regionality, account main.session
Traceback (most recent call last):
  File "C:\Users\пользователь\Desktop\Бот коменнст\comments\main.py", line 279, in join_channel
    res = await client(JoinChannelRequest(await client.get_input_entity(link)))
          ^^^^^^^^^^^^^^^^^^^^^^^^^^^^^^^^^^^^^^^^^^^^^^^^^^^^^^^^^^^^^^^^^^^^^
  File "C:\Users\пользователь\AppData\Roaming\Python\Python311\site-packages\telethon\client\users.py", line 30, in __call__
    return await self._call(self._sender, request, ordered=ordered)
           ^^^^^^^^^^^^^^^^^^^^^^^^^^^^^^^^^^^^^^^^^^^^^^^^^^^^^^^^
  File "C:\Users\пользователь\AppData\Roaming\Python\Python311\site-packages\telethon\client\users.py", line 52, in _call
    raise errors.FloodWaitError(request=r, capture=diff)
telethon.errors.rpcerrorlist.FloodWaitError: A wait of 96 seconds is required (caused by JoinChannelRequest)

channel https://t.me/BilaTserkvaBT, account main.session
Traceback (most recent call last):
  File "C:\Users\пользователь\Desktop\Бот коменнст\comments\main.py", line 279, in join_channel
    res = await client(JoinChannelRequest(await client.get_input_entity(link)))
          ^^^^^^^^^^^^^^^^^^^^^^^^^^^^^^^^^^^^^^^^^^^^^^^^^^^^^^^^^^^^^^^^^^^^^
  File "C:\Users\пользователь\AppData\Roaming\Python\Python311\site-packages\telethon\client\users.py", line 30, in __call__
    return await self._call(self._sender, request, ordered=ordered)
           ^^^^^^^^^^^^^^^^^^^^^^^^^^^^^^^^^^^^^^^^^^^^^^^^^^^^^^^^
  File "C:\Users\пользователь\AppData\Roaming\Python\Python311\site-packages\telethon\client\users.py", line 52, in _call
    raise errors.FloodWaitError(request=r, capture=diff)
telethon.errors.rpcerrorlist.FloodWaitError: A wait of 93 seconds is required (caused by JoinChannelRequest)

channel https://t.me/Chennel_33TV, account main.session
Traceback (most recent call last):
  File "C:\Users\пользователь\Desktop\Бот коменнст\comments\main.py", line 279, in join_channel
    res = await client(JoinChannelRequest(await client.get_input_entity(link)))
          ^^^^^^^^^^^^^^^^^^^^^^^^^^^^^^^^^^^^^^^^^^^^^^^^^^^^^^^^^^^^^^^^^^^^^
  File "C:\Users\пользователь\AppData\Roaming\Python\Python311\site-packages\telethon\client\users.py", line 30, in __call__
    return await self._call(self._sender, request, ordered=ordered)
           ^^^^^^^^^^^^^^^^^^^^^^^^^^^^^^^^^^^^^^^^^^^^^^^^^^^^^^^^
  File "C:\Users\пользователь\AppData\Roaming\Python\Python311\site-packages\telethon\client\users.py", line 52, in _call
    raise errors.FloodWaitError(request=r, capture=diff)
telethon.errors.rpcerrorlist.FloodWaitError: A wait of 91 seconds is required (caused by JoinChannelRequest)

channel https://t.me/nnxkkksl, account main.session
Traceback (most recent call last):
  File "C:\Users\пользователь\Desktop\Бот коменнст\comments\main.py", line 279, in join_channel
    res = await client(JoinChannelRequest(await client.get_input_entity(link)))
          ^^^^^^^^^^^^^^^^^^^^^^^^^^^^^^^^^^^^^^^^^^^^^^^^^^^^^^^^^^^^^^^^^^^^^
  File "C:\Users\пользователь\AppData\Roaming\Python\Python311\site-packages\telethon\client\users.py", line 30, in __call__
    return await self._call(self._sender, request, ordered=ordered)
           ^^^^^^^^^^^^^^^^^^^^^^^^^^^^^^^^^^^^^^^^^^^^^^^^^^^^^^^^
  File "C:\Users\пользователь\AppData\Roaming\Python\Python311\site-packages\telethon\client\users.py", line 52, in _call
    raise errors.FloodWaitError(request=r, capture=diff)
telethon.errors.rpcerrorlist.FloodWaitError: A wait of 88 seconds is required (caused by JoinChannelRequest)

channel IwWCKB8933RkMTMy, account +380 68 612 76 31.session
Traceback (most recent call last):
  File "C:\Users\пользователь\Desktop\Бот коменнст\comments\main.py", line 243, in join_channel
    res = await client(ImportChatInviteRequest(hash=link))
          ^^^^^^^^^^^^^^^^^^^^^^^^^^^^^^^^^^^^^^^^^^^^^^^^
  File "C:\Users\пользователь\AppData\Roaming\Python\Python311\site-packages\telethon\client\users.py", line 30, in __call__
    return await self._call(self._sender, request, ordered=ordered)
           ^^^^^^^^^^^^^^^^^^^^^^^^^^^^^^^^^^^^^^^^^^^^^^^^^^^^^^^^
  File "C:\Users\пользователь\AppData\Roaming\Python\Python311\site-packages\telethon\client\users.py", line 84, in _call
    result = await future
             ^^^^^^^^^^^^
telethon.errors.rpcerrorlist.UserAlreadyParticipantError: The authenticated user is already a participant of the chat (caused by ImportChatInviteRequest)

channel IwWCKB8933RkMTMy, account main.session
Traceback (most recent call last):
  File "C:\Users\пользователь\Desktop\Бот коменнст\comments\main.py", line 243, in join_channel
    res = await client(ImportChatInviteRequest(hash=link))
          ^^^^^^^^^^^^^^^^^^^^^^^^^^^^^^^^^^^^^^^^^^^^^^^^
  File "C:\Users\пользователь\AppData\Roaming\Python\Python311\site-packages\telethon\client\users.py", line 30, in __call__
    return await self._call(self._sender, request, ordered=ordered)
           ^^^^^^^^^^^^^^^^^^^^^^^^^^^^^^^^^^^^^^^^^^^^^^^^^^^^^^^^
  File "C:\Users\пользователь\AppData\Roaming\Python\Python311\site-packages\telethon\client\users.py", line 84, in _call
    result = await future
             ^^^^^^^^^^^^
telethon.errors.rpcerrorlist.UserAlreadyParticipantError: The authenticated user is already a participant of the chat (caused by ImportChatInviteRequest)

channel arkbFg-HLAZlYjJi, account +380 68 612 76 31.session
Traceback (most recent call last):
  File "C:\Users\пользователь\Desktop\Бот коменнст\comments\main.py", line 243, in join_channel
    res = await client(ImportChatInviteRequest(hash=link))
          ^^^^^^^^^^^^^^^^^^^^^^^^^^^^^^^^^^^^^^^^^^^^^^^^
  File "C:\Users\пользователь\AppData\Roaming\Python\Python311\site-packages\telethon\client\users.py", line 30, in __call__
    return await self._call(self._sender, request, ordered=ordered)
           ^^^^^^^^^^^^^^^^^^^^^^^^^^^^^^^^^^^^^^^^^^^^^^^^^^^^^^^^
  File "C:\Users\пользователь\AppData\Roaming\Python\Python311\site-packages\telethon\client\users.py", line 84, in _call
    result = await future
             ^^^^^^^^^^^^
telethon.errors.rpcerrorlist.UserAlreadyParticipantError: The authenticated user is already a participant of the chat (caused by ImportChatInviteRequest)

channel arkbFg-HLAZlYjJi, account main.session
Traceback (most recent call last):
  File "C:\Users\пользователь\Desktop\Бот коменнст\comments\main.py", line 243, in join_channel
    res = await client(ImportChatInviteRequest(hash=link))
          ^^^^^^^^^^^^^^^^^^^^^^^^^^^^^^^^^^^^^^^^^^^^^^^^
  File "C:\Users\пользователь\AppData\Roaming\Python\Python311\site-packages\telethon\client\users.py", line 30, in __call__
    return await self._call(self._sender, request, ordered=ordered)
           ^^^^^^^^^^^^^^^^^^^^^^^^^^^^^^^^^^^^^^^^^^^^^^^^^^^^^^^^
  File "C:\Users\пользователь\AppData\Roaming\Python\Python311\site-packages\telethon\client\users.py", line 84, in _call
    result = await future
             ^^^^^^^^^^^^
telethon.errors.rpcerrorlist.UserAlreadyParticipantError: The authenticated user is already a participant of the chat (caused by ImportChatInviteRequest)

Traceback (most recent call last):
  File "C:\Users\пользователь\Desktop\Бот коменнст\comments\main.py", line 478, in my_event_handler
    await acc.send_message(event.message.chat.id, message=settings["msg"], comment_to=post)
  File "C:\Users\пользователь\AppData\Roaming\Python\Python311\site-packages\telethon\client\messages.py", line 890, in send_message
    result = await self(request)
             ^^^^^^^^^^^^^^^^^^^
  File "C:\Users\пользователь\AppData\Roaming\Python\Python311\site-packages\telethon\client\users.py", line 30, in __call__
    return await self._call(self._sender, request, ordered=ordered)
           ^^^^^^^^^^^^^^^^^^^^^^^^^^^^^^^^^^^^^^^^^^^^^^^^^^^^^^^^
  File "C:\Users\пользователь\AppData\Roaming\Python\Python311\site-packages\telethon\client\users.py", line 84, in _call
    result = await future
             ^^^^^^^^^^^^
telethon.errors.rpcerrorlist.ChannelPrivateError: The channel specified is private and you lack permission to access it. Another reason may be that you were banned from it (caused by SendMessageRequest)

test
Traceback (most recent call last):
  File "C:\Users\пользователь\Desktop\Бот коменнст\comments\main.py", line 455, in my_event_handler
    await acc.connect()
  File "C:\Users\пользователь\AppData\Roaming\Python\Python311\site-packages\telethon\client\telegrambaseclient.py", line 567, in connect
    me = await self.get_me()
         ^^^^^^^^^^^^^^^^^^^
  File "C:\Users\пользователь\AppData\Roaming\Python\Python311\site-packages\telethon\client\users.py", line 161, in get_me
    me = (await self(
          ^^^^^^^^^^^
  File "C:\Users\пользователь\AppData\Roaming\Python\Python311\site-packages\telethon\client\users.py", line 30, in __call__
    return await self._call(self._sender, request, ordered=ordered)
           ^^^^^^^^^^^^^^^^^^^^^^^^^^^^^^^^^^^^^^^^^^^^^^^^^^^^^^^^
  File "C:\Users\пользователь\AppData\Roaming\Python\Python311\site-packages\telethon\client\users.py", line 85, in _call
    self.session.process_entities(result)
  File "C:\Users\пользователь\AppData\Roaming\Python\Python311\site-packages\telethon\sessions\sqlite.py", line 301, in process_entities
    c.executemany(
sqlite3.OperationalError: database is locked

Traceback (most recent call last):
  File "C:\Users\пользователь\Desktop\Бот коменнст\comments\main.py", line 455, in my_event_handler
    await acc.connect()
  File "C:\Users\пользователь\AppData\Roaming\Python\Python311\site-packages\telethon\client\telegrambaseclient.py", line 540, in connect
    self.session.auth_key = self._sender.auth_key
    ^^^^^^^^^^^^^^^^^^^^^
  File "C:\Users\пользователь\AppData\Roaming\Python\Python311\site-packages\telethon\sessions\sqlite.py", line 180, in auth_key
    self._update_session_table()
  File "C:\Users\пользователь\AppData\Roaming\Python\Python311\site-packages\telethon\sessions\sqlite.py", line 194, in _update_session_table
    c.execute('delete from sessions')
sqlite3.OperationalError: database is locked

Traceback (most recent call last):
  File "C:\Users\пользователь\Desktop\Бот коменнст\comments\main.py", line 455, in my_event_handler
    await acc.connect()
  File "C:\Users\пользователь\AppData\Roaming\Python\Python311\site-packages\telethon\client\telegrambaseclient.py", line 540, in connect
    self.session.auth_key = self._sender.auth_key
    ^^^^^^^^^^^^^^^^^^^^^
  File "C:\Users\пользователь\AppData\Roaming\Python\Python311\site-packages\telethon\sessions\sqlite.py", line 180, in auth_key
    self._update_session_table()
  File "C:\Users\пользователь\AppData\Roaming\Python\Python311\site-packages\telethon\sessions\sqlite.py", line 194, in _update_session_table
    c.execute('delete from sessions')
sqlite3.OperationalError: database is locked

Traceback (most recent call last):
  File "C:\Users\пользователь\Desktop\Бот коменнст\comments\main.py", line 455, in my_event_handler
    await acc.connect()
  File "C:\Users\пользователь\AppData\Roaming\Python\Python311\site-packages\telethon\client\telegrambaseclient.py", line 540, in connect
    self.session.auth_key = self._sender.auth_key
    ^^^^^^^^^^^^^^^^^^^^^
  File "C:\Users\пользователь\AppData\Roaming\Python\Python311\site-packages\telethon\sessions\sqlite.py", line 180, in auth_key
    self._update_session_table()
  File "C:\Users\пользователь\AppData\Roaming\Python\Python311\site-packages\telethon\sessions\sqlite.py", line 194, in _update_session_table
    c.execute('delete from sessions')
sqlite3.OperationalError: database is locked

Traceback (most recent call last):
  File "C:\Users\пользователь\Desktop\Бот коменнст\comments\main.py", line 455, in my_event_handler
    await acc.connect()
  File "C:\Users\пользователь\AppData\Roaming\Python\Python311\site-packages\telethon\client\telegrambaseclient.py", line 540, in connect
    self.session.auth_key = self._sender.auth_key
    ^^^^^^^^^^^^^^^^^^^^^
  File "C:\Users\пользователь\AppData\Roaming\Python\Python311\site-packages\telethon\sessions\sqlite.py", line 180, in auth_key
    self._update_session_table()
  File "C:\Users\пользователь\AppData\Roaming\Python\Python311\site-packages\telethon\sessions\sqlite.py", line 194, in _update_session_table
    c.execute('delete from sessions')
sqlite3.OperationalError: database is locked

